<robot name="simple_bot">
  <link name="base_link">
    <visual>
      <geometry>
        <box size="0.4 0.3 0.2"/>
      </geometry>
    </visual>
    <collision>
      <geometry>
        <box size="0.4 0.3 0.2"/>
      </geometry>
    </collision>
    <inertial>
      <mass value="1"/>
      <origin xyz="0 0 0"/>
      <inertia ixx="0.01" iyy="0.01" izz="0.01" ixy="0.0" ixz="0.0" iyz="0.0"/>
    </inertial>
  </link>

  <!-- left wheel -->
  <link name="left_wheel"/>
  <joint name="left_wheel_joint" type="continuous">
    <parent link="base_link"/>
    <child link="left_wheel"/>
    <origin xyz="0 0.15 0" rpy="0 0 0"/>
    <axis xyz="0 1 0"/>
  </joint>

  <!-- right wheel -->
  <link name="right_wheel"/>
  <joint name="right_wheel_joint" type="continuous">
    <parent link="base_link"/>
    <child link="right_wheel"/>
    <origin xyz="0 -0.15 0" rpy="0 0 0"/>
    <axis xyz="0 1 0"/>
  </joint>
</robot>
